Workbook

Sheet Сітка
A1: ПАРАМЕТРИ ЛОТУ
A2: № з/п | B2: Найменування послуг | C2: № лоту | D2: Відмітка про надання послуг | E2: Обсяг надання послуг | F2: Од. виміру | G2: Гранична ціна без ПДВ, грн/од. виміру | H2: Коефіцієнт частки вартості | I2: Вартість надання послуг без ПДВ, грн | J2: Початкова ціна лоту без ПДВ, грн | K2: Тендерна пропозиція УЧАСНИКА без ПДВ, грн
A3: =Дані!A183 -> 1 | B3: =Дані!B183 -> Обробіток грунту | C3: - | D3: =IF($E3="-", "ні", "так") -> ні | E3: =IF(C$3="-", "-", IF(C$3=1, Дані!$D183, IF(C$3=2, Дані!$E183, IF(C$3=3, Дані!$F183, IF(C$3=4, Дані!$G183, IF(C$3=5, Дані!$H183, IF(C$3=6, Дані!$I183, IF(C$3=7, Дані!$J183, IF(C$3=8, Дані!$K183, IF(C$3=9, Дані!$L183, IF(C$3=10, Дані!$M183, "") ) ) ) ) ) ) ) ) ) ) -> - | F3: =Дані!C183 -> м2 | G3: =IFERROR(ROUND(I3/E3,6),"-") -> - | H3: =IF(C$3="-", "-", IF(C$3=1, Дані!$D249, IF(C$3=2, Дані!$E249, IF(C$3=3, Дані!$F249, IF(C$3=4, Дані!$G249, IF(C$3=5, Дані!$H249, IF(C$3=6, Дані!$I249, IF(C$3=7, Дані!$J249, IF(C$3=8, Дані!$K249, IF(C$3=9, Дані!$L249, IF(C$3=10, Дані!$M249, "") ) ) ) ) ) ) ) ) ) ) -> - | I3: =IFERROR(IF(OR(H3="-", H3=0), "-", IF(COUNTIF(H4:$H$31,">0")=0, K$3-SUMIF($I$2:I2,">0"), ROUND(K$3*H3, 2))), "-") -> - | J3: =IF(C3="-", "-", IF(C3=1, Дані!D244, IF(C3=2, Дані!E244, IF(C3=3, Дані!F244, IF(C3=4, Дані!G244, IF(C3=5, Дані!H244, IF(C3=6, Дані!I244, IF(C3=7, Дані!J244, IF(C3=8,Дані!K244, IF(C3=9, Дані!L244, IF(C3=10, Дані!M244, "") ) ) ) ) ) ) ) ) ) ) -> -
A4: =Дані!A184 -> 2 | B4: =Дані!B184 -> Перекопування та планування обробленого ґрунту | D4: =IF($E4="-", "ні", "так") -> ні | E4: =IF(C$3="-", "-", IF(C$3=1, Дані!$D184, IF(C$3=2, Дані!$E184, IF(C$3=3, Дані!$F184, IF(C$3=4, Дані!$G184, IF(C$3=5, Дані!$H184, IF(C$3=6, Дані!$I184, IF(C$3=7, Дані!$J184, IF(C$3=8, Дані!$K184, IF(C$3=9, Дані!$L184, IF(C$3=10, Дані!$M184, "") ) ) ) ) ) ) ) ) ) ) -> - | F4: =Дані!C184 -> м2 | G4: =IFERROR(ROUND(I4/E4,6),"-") -> - | H4: =IF(C$3="-", "-", IF(C$3=1, Дані!$D250, IF(C$3=2, Дані!$E250, IF(C$3=3, Дані!$F250, IF(C$3=4, Дані!$G250, IF(C$3=5, Дані!$H250, IF(C$3=6, Дані!$I250, IF(C$3=7, Дані!$J250, IF(C$3=8, Дані!$K250, IF(C$3=9, Дані!$L250, IF(C$3=10, Дані!$M250, "") ) ) ) ) ) ) ) ) ) ) -> - | I4: =IFERROR(IF(OR(H4="-", H4=0), "-", IF(COUNTIF(H5:$H$31,">0")=0, K$3-SUMIF($I$2:I3,">0"), ROUND(K$3*H4, 2))), "-") -> -
A5: =Дані!A185 -> 3 | B5: =Дані!B185 -> Підготовка насіння до висівання | D5: =IF($E5="-", "ні", "так") -> ні | E5: =IF(C$3="-", "-", IF(C$3=1, Дані!$D185, IF(C$3=2, Дані!$E185, IF(C$3=3, Дані!$F185, IF(C$3=4, Дані!$G185, IF(C$3=5, Дані!$H185, IF(C$3=6, Дані!$I185, IF(C$3=7, Дані!$J185, IF(C$3=8, Дані!$K185, IF(C$3=9, Дані!$L185, IF(C$3=10, Дані!$M185, "") ) ) ) ) ) ) ) ) ) ) -> - | F5: =Дані!C185 -> кг | G5: =IFERROR(ROUND(I5/E5,6),"-") -> - | H5: =IF(C$3="-", "-", IF(C$3=1, Дані!$D251, IF(C$3=2, Дані!$E251, IF(C$3=3, Дані!$F251, IF(C$3=4, Дані!$G251, IF(C$3=5, Дані!$H251, IF(C$3=6, Дані!$I251, IF(C$3=7, Дані!$J251, IF(C$3=8, Дані!$K251, IF(C$3=9, Дані!$L251, IF(C$3=10, Дані!$M251, "") ) ) ) ) ) ) ) ) ) ) -> - | I5: =IFERROR(IF(OR(H5="-", H5=0), "-", IF(COUNTIF(H6:$H$31,">0")=0, K$3-SUMIF($I$2:I4,">0"), ROUND(K$3*H5, 2))), "-") -> -
A6: =Дані!A186 -> 4 | B6: =Дані!B186 -> Стратифікація, зволоження та протруювання насіння | D6: =IF($E6="-", "ні", "так") -> ні | E6: =IF(C$3="-", "-", IF(C$3=1, Дані!$D186, IF(C$3=2, Дані!$E186, IF(C$3=3, Дані!$F186, IF(C$3=4, Дані!$G186, IF(C$3=5, Дані!$H186, IF(C$3=6, Дані!$I186, IF(C$3=7, Дані!$J186, IF(C$3=8, Дані!$K186, IF(C$3=9, Дані!$L186, IF(C$3=10, Дані!$M186, "") ) ) ) ) ) ) ) ) ) ) -> - | F6: =Дані!C186 -> кг | G6: =IFERROR(ROUND(I6/E6,6),"-") -> - | H6: =IF(C$3="-", "-", IF(C$3=1, Дані!$D252, IF(C$3=2, Дані!$E252, IF(C$3=3, Дані!$F252, IF(C$3=4, Дані!$G252, IF(C$3=5, Дані!$H252, IF(C$3=6, Дані!$I252, IF(C$3=7, Дані!$J252, IF(C$3=8, Дані!$K252, IF(C$3=9, Дані!$L252, IF(C$3=10, Дані!$M252, "") ) ) ) ) ) ) ) ) ) ) -> - | I6: =IFERROR(IF(OR(H6="-", H6=0), "-", IF(COUNTIF(H7:$H$31,">0")=0, K$3-SUMIF($I$2:I5,">0"), ROUND(K$3*H6, 2))), "-") -> -
A7: =Дані!A187 -> 5 | B7: =Дані!B187 -> Снігування насіння | D7: =IF($E7="-", "ні", "так") -> ні | E7: =IF(C$3="-", "-", IF(C$3=1, Дані!$D187, IF(C$3=2, Дані!$E187, IF(C$3=3, Дані!$F187, IF(C$3=4, Дані!$G187, IF(C$3=5, Дані!$H187, IF(C$3=6, Дані!$I187, IF(C$3=7, Дані!$J187, IF(C$3=8, Дані!$K187, IF(C$3=9, Дані!$L187, IF(C$3=10, Дані!$M187, "") ) ) ) ) ) ) ) ) ) ) -> - | F7: =Дані!C187 -> кг | G7: =IFERROR(ROUND(I7/E7,6),"-") -> - | H7: =IF(C$3="-", "-", IF(C$3=1, Дані!$D253, IF(C$3=2, Дані!$E253, IF(C$3=3, Дані!$F253, IF(C$3=4, Дані!$G253, IF(C$3=5, Дані!$H253, IF(C$3=6, Дані!$I253, IF(C$3=7, Дані!$J253, IF(C$3=8, Дані!$K253, IF(C$3=9, Дані!$L253, IF(C$3=10, Дані!$M253, "") ) ) ) ) ) ) ) ) ) ) -> - | I7: =IFERROR(IF(OR(H7="-", H7=0), "-", IF(COUNTIF(H8:$H$31,">0")=0, K$3-SUMIF($I$2:I6,">0"), ROUND(K$3*H7, 2))), "-") -> -
A8: =Дані!A188 -> 6 | B8: =Дані!B188 -> Заготівля снігу та льоду для снігування насіння з піднесенням до 50 м | D8: =IF($E8="-", "ні", "так") -> ні | E8: =IF(C$3="-", "-", IF(C$3=1, Дані!$D188, IF(C$3=2, Дані!$E188, IF(C$3=3, Дані!$F188, IF(C$3=4, Дані!$G188, IF(C$3=5, Дані!$H188, IF(C$3=6, Дані!$I188, IF(C$3=7, Дані!$J188, IF(C$3=8, Дані!$K188, IF(C$3=9, Дані!$L188, IF(C$3=10, Дані!$M188, "") ) ) ) ) ) ) ) ) ) ) -> - | F8: =Дані!C188 -> м3 | G8: =IFERROR(ROUND(I8/E8,6),"-") -> - | H8: =IF(C$3="-", "-", IF(C$3=1, Дані!$D254, IF(C$3=2, Дані!$E254, IF(C$3=3, Дані!$F254, IF(C$3=4, Дані!$G254, IF(C$3=5, Дані!$H254, IF(C$3=6, Дані!$I254, IF(C$3=7, Дані!$J254, IF(C$3=8, Дані!$K254, IF(C$3=9, Дані!$L254, IF(C$3=10, Дані!$M254, "") ) ) ) ) ) ) ) ) ) ) -> - | I8: =IFERROR(IF(OR(H8="-", H8=0), "-", IF(COUNTIF(H9:$H$31,">0")=0, K$3-SUMIF($I$2:I7,">0"), ROUND(K$3*H8, 2))), "-") -> -
A9: =Дані!A189 -> 7 | B9: =Дані!B189 -> Висівання насіння | D9: =IF($E9="-", "ні", "так") -> ні | E9: =IF(C$3="-", "-", IF(C$3=1, Дані!$D189, IF(C$3=2, Дані!$E189, IF(C$3=3, Дані!$F189, IF(C$3=4, Дані!$G189, IF(C$3=5, Дані!$H189, IF(C$3=6, Дані!$I189, IF(C$3=7, Дані!$J189, IF(C$3=8, Дані!$K189, IF(C$3=9, Дані!$L189, IF(C$3=10, Дані!$M189, "") ) ) ) ) ) ) ) ) ) ) -> - | F9: =Дані!C189 -> тис. пог. м. | G9: =IFERROR(ROUND(I9/E9,6),"-") -> - | H9: =IF(C$3="-", "-", IF(C$3=1, Дані!$D255, IF(C$3=2, Дані!$E255, IF(C$3=3, Дані!$F255, IF(C$3=4, Дані!$G255, IF(C$3=5, Дані!$H255, IF(C$3=6, Дані!$I255, IF(C$3=7, Дані!$J255, IF(C$3=8, Дані!$K255, IF(C$3=9, Дані!$L255, IF(C$3=10, Дані!$M255, "") ) ) ) ) ) ) ) ) ) ) -> - | I9: =IFERROR(IF(OR(H9="-", H9=0), "-", IF(COUNTIF(H10:$H$31,">0")=0, K$3-SUMIF($I$2:I8,">0"), ROUND(K$3*H9, 2))), "-") -> -
A10: =Дані!A190 -> 8 | B10: =Дані!B190 -> Висівання насіння в короби та теплиці | D10: =IF($E10="-", "ні", "так") -> ні | E10: =IF(C$3="-", "-", IF(C$3=1, Дані!$D190, IF(C$3=2, Дані!$E190, IF(C$3=3, Дані!$F190, IF(C$3=4, Дані!$G190, IF(C$3=5, Дані!$H190, IF(C$3=6, Дані!$I190, IF(C$3=7, Дані!$J190, IF(C$3=8, Дані!$K190, IF(C$3=9, Дані!$L190, IF(C$3=10, Дані!$M190, "") ) ) ) ) ) ) ) ) ) ) -> - | F10: =Дані!C190 -> м2 | G10: =IFERROR(ROUND(I10/E10,6),"-") -> - | H10: =IF(C$3="-", "-", IF(C$3=1, Дані!$D256, IF(C$3=2, Дані!$E256, IF(C$3=3, Дані!$F256, IF(C$3=4, Дані!$G256, IF(C$3=5, Дані!$H256, IF(C$3=6, Дані!$I256, IF(C$3=7, Дані!$J256, IF(C$3=8, Дані!$K256, IF(C$3=9, Дані!$L256, IF(C$3=10, Дані!$M256, "") ) ) ) ) ) ) ) ) ) ) -> - | I10: =IFERROR(IF(OR(H10="-", H10=0), "-", IF(COUNTIF(H11:$H$31,">0")=0, K$3-SUMIF($I$2:I9,">0"), ROUND(K$3*H10, 2))), "-") -> -
A11: =Дані!A191 -> 9 | B11: =Дані!B191 -> Висівання у касети | D11: =IF($E11="-", "ні", "так") -> ні | E11: =IF(C$3="-", "-", IF(C$3=1, Дані!$D191, IF(C$3=2, Дані!$E191, IF(C$3=3, Дані!$F191, IF(C$3=4, Дані!$G191, IF(C$3=5, Дані!$H191, IF(C$3=6, Дані!$I191, IF(C$3=7, Дані!$J191, IF(C$3=8, Дані!$K191, IF(C$3=9, Дані!$L191, IF(C$3=10, Дані!$M191, "") ) ) ) ) ) ) ) ) ) ) -> - | F11: =Дані!C191 -> касета | G11: =IFERROR(ROUND(I11/E11,6),"-") -> - | H11: =IF(C$3="-", "-", IF(C$3=1, Дані!$D257, IF(C$3=2, Дані!$E257, IF(C$3=3, Дані!$F257, IF(C$3=4, Дані!$G257, IF(C$3=5, Дані!$H257, IF(C$3=6, Дані!$I257, IF(C$3=7, Дані!$J257, IF(C$3=8, Дані!$K257, IF(C$3=9, Дані!$L257, IF(C$3=10, Дані!$M257, "") ) ) ) ) ) ) ) ) ) ) -> - | I11: =IFERROR(IF(OR(H11="-", H11=0), "-", IF(COUNTIF(H12:$H$31,">0")=0, K$3-SUMIF($I$2:I10,">0"), ROUND(K$3*H11, 2))), "-") -> -
A12: =Дані!A192 -> 10 | B12: =Дані!B192 -> Догляд за сіянцями та саджанцями | D12: =IF($E12="-", "ні", "так") -> ні | E12: =IF(C$3="-", "-", IF(C$3=1, Дані!$D192, IF(C$3=2, Дані!$E192, IF(C$3=3, Дані!$F192, IF(C$3=4, Дані!$G192, IF(C$3=5, Дані!$H192, IF(C$3=6, Дані!$I192, IF(C$3=7, Дані!$J192, IF(C$3=8, Дані!$K192, IF(C$3=9, Дані!$L192, IF(C$3=10, Дані!$M192, "") ) ) ) ) ) ) ) ) ) ) -> - | F12: =Дані!C192 -> м2 | G12: =IFERROR(ROUND(I12/E12,6),"-") -> - | H12: =IF(C$3="-", "-", IF(C$3=1, Дані!$D258, IF(C$3=2, Дані!$E258, IF(C$3=3, Дані!$F258, IF(C$3=4, Дані!$G258, IF(C$3=5, Дані!$H258, IF(C$3=6, Дані!$I258, IF(C$3=7, Дані!$J258, IF(C$3=8, Дані!$K258, IF(C$3=9, Дані!$L258, IF(C$3=10, Дані!$M258, "") ) ) ) ) ) ) ) ) ) ) -> - | I12: =IFERROR(IF(OR(H12="-", H12=0), "-", IF(COUNTIF(H13:$H$31,">0")=0, K$3-SUMIF($I$2:I11,">0"), ROUND(K$3*H12, 2))), "-") -> -
A13: =Дані!A193 -> 11 | B13: =Дані!B193 -> Покривання сіянців та саджанців затіняючою сіткою, плівкою, агроволокном | D13: =IF($E13="-", "ні", "так") -> ні | E13: =IF(C$3="-", "-", IF(C$3=1, Дані!$D193, IF(C$3=2, Дані!$E193, IF(C$3=3, Дані!$F193, IF(C$3=4, Дані!$G193, IF(C$3=5, Дані!$H193, IF(C$3=6, Дані!$I193, IF(C$3=7, Дані!$J193, IF(C$3=8, Дані!$K193, IF(C$3=9, Дані!$L193, IF(C$3=10, Дані!$M193, "") ) ) ) ) ) ) ) ) ) ) -> - | F13: =Дані!C193 -> м2 | G13: =IFERROR(ROUND(I13/E13,6),"-") -> - | H13: =IF(C$3="-", "-", IF(C$3=1, Дані!$D259, IF(C$3=2, Дані!$E259, IF(C$3=3, Дані!$F259, IF(C$3=4, Дані!$G259, IF(C$3=5, Дані!$H259, IF(C$3=6, Дані!$I259, IF(C$3=7, Дані!$J259, IF(C$3=8, Дані!$K259, IF(C$3=9, Дані!$L259, IF(C$3=10, Дані!$M259, "") ) ) ) ) ) ) ) ) ) ) -> - | I13: =IFERROR(IF(OR(H13="-", H13=0), "-", IF(COUNTIF(H14:$H$31,">0")=0, K$3-SUMIF($I$2:I12,">0"), ROUND(K$3*H13, 2))), "-") -> -
A14: =Дані!A194 -> 12 | B14: =Дані!B194 -> Обприскування та підживлення рослин | D14: =IF($E14="-", "ні", "так") -> ні | E14: =IF(C$3="-", "-", IF(C$3=1, Дані!$D194, IF(C$3=2, Дані!$E194, IF(C$3=3, Дані!$F194, IF(C$3=4, Дані!$G194, IF(C$3=5, Дані!$H194, IF(C$3=6, Дані!$I194, IF(C$3=7, Дані!$J194, IF(C$3=8, Дані!$K194, IF(C$3=9, Дані!$L194, IF(C$3=10, Дані!$M194, "") ) ) ) ) ) ) ) ) ) ) -> - | F14: =Дані!C194 -> м2 | G14: =IFERROR(ROUND(I14/E14,6),"-") -> - | H14: =IF(C$3="-", "-", IF(C$3=1, Дані!$D260, IF(C$3=2, Дані!$E260, IF(C$3=3, Дані!$F260, IF(C$3=4, Дані!$G260, IF(C$3=5, Дані!$H260, IF(C$3=6, Дані!$I260, IF(C$3=7, Дані!$J260, IF(C$3=8, Дані!$K260, IF(C$3=9, Дані!$L260, IF(C$3=10, Дані!$M260, "") ) ) ) ) ) ) ) ) ) ) -> - | I14: =IFERROR(IF(OR(H14="-", H14=0), "-", IF(COUNTIF(H15:$H$31,">0")=0, K$3-SUMIF($I$2:I13,">0"), ROUND(K$3*H14, 2))), "-") -> -
A15: =Дані!A195 -> 13 | B15: =Дані!B195 -> Прополювання посівів у теплицях або коробах | D15: =IF($E15="-", "ні", "так") -> ні | E15: =IF(C$3="-", "-", IF(C$3=1, Дані!$D195, IF(C$3=2, Дані!$E195, IF(C$3=3, Дані!$F195, IF(C$3=4, Дані!$G195, IF(C$3=5, Дані!$H195, IF(C$3=6, Дані!$I195, IF(C$3=7, Дані!$J195, IF(C$3=8, Дані!$K195, IF(C$3=9, Дані!$L195, IF(C$3=10, Дані!$M195, "") ) ) ) ) ) ) ) ) ) ) -> - | F15: =Дані!C195 -> м2 | G15: =IFERROR(ROUND(I15/E15,6),"-") -> - | H15: =IF(C$3="-", "-", IF(C$3=1, Дані!$D261, IF(C$3=2, Дані!$E261, IF(C$3=3, Дані!$F261, IF(C$3=4, Дані!$G261, IF(C$3=5, Дані!$H261, IF(C$3=6, Дані!$I261, IF(C$3=7, Дані!$J261, IF(C$3=8, Дані!$K261, IF(C$3=9, Дані!$L261, IF(C$3=10, Дані!$M261, "") ) ) ) ) ) ) ) ) ) ) -> - | I15: =IFERROR(IF(OR(H15="-", H15=0), "-", IF(COUNTIF(H16:$H$31,">0")=0, K$3-SUMIF($I$2:I14,">0"), ROUND(K$3*H15, 2))), "-") -> -
... A30: =Дані!A210 -> 28 | B30: =Дані!B210 -> Формування крон у новорічних дерев | D30: =IF($E30="-", "ні", "так") -> ні | E30: =IF(C$3="-", "-", IF(C$3=1, Дані!$D210, IF(C$3=2, Дані!$E210, IF(C$3=3, Дані!$F210, IF(C$3=4, Дані!$G210, IF(C$3=5, Дані!$H210, IF(C$3=6, Дані!$I210, IF(C$3=7, Дані!$J210, IF(C$3=8, Дані!$K210, IF(C$3=9, Дані!$L210, IF(C$3=10, Дані!$M210, "") ) ) ) ) ) ) ) ) ) ) -> - | F30: =Дані!C210 -> шт. | G30: =IFERROR(ROUND(I30/E30,6),"-") -> - | H30: =IF(C$3="-", "-", IF(C$3=1, Дані!$D276, IF(C$3=2, Дані!$E276, IF(C$3=3, Дані!$F276, IF(C$3=4, Дані!$G276, IF(C$3=5, Дані!$H276, IF(C$3=6, Дані!$I276, IF(C$3=7, Дані!$J276, IF(C$3=8, Дані!$K276, IF(C$3=9, Дані!$L276, IF(C$3=10, Дані!$M276, "") ) ) ) ) ) ) ) ) ) ) -> - | I30: =IFERROR(IF(OR(H30="-", H30=0), "-", IF(COUNTIF(H31:$H$31,">0")=0, K$3-SUMIF($I$2:I29,">0"), ROUND(K$3*H30, 2))), "-") -> -
A31: СІТКА РОЗЦІНОК на надання лісокультурних послуг
A32: № з/п | B32: Найменування послуг | G32: Ціна, без ПДВ | H32: Коефіцієнт ціни | K32: =MID("0123456789", INT(RAND()*10)+1, 1) & MID("ABCDEFGHIJKLMNOPQRSTUVWXYZ", INT(RAND()*26)+1, 1) & MID("0123456789", INT(RAND()*10)+1, 1) & MID("ABCDEFGHIJKLMNOPQRSTUVWXYZ", INT(RAND()*26)+1, 1) & MID("0123456789", INT(RAND()*10)+1, 1) & MID("ABCDEFGHIJKLMNOPQRSTUVWXYZ", INT(RAND()*26)+1, 1) -> 1J3O0Q
A33: =Дані!A3 -> 1. | B33: =Дані!B3 -> Обробіток грунту: | G33: грн/м2 | J33: id: | K33: 5Y8X2A
A34: =Дані!A4 -> 1.1. | B34: =Дані!B4 -> - боронування всіх різновидностей грунту в один слід бороною | G34: =IFERROR(ROUND(H34*$G$3,2), "-") -> - | H34: =Дані!C4 -> 0.061728395 | I34: =MID("0123456789ABCDEFGHIJKLMNOPQRSTUVWXYZ", MOD(NOW()*8640000,36)+1, 1) & MID("0123456789ABCDEFGHIJKLMNOPQRSTUVWXYZ", INT(RAND()*36)+1, 1) & MID("0123456789ABCDEFGHIJKLMNOPQRSTUVWXYZ", MOD(NOW()*864000000,36)+1, 1) & MID("0123456789ABCDEFGHIJKLMNOPQRSTUVWXYZ", INT(RAND()*36)+1, 1) & MID("0123456789ABCDEFGHIJKLMNOPQRSTUVWXYZ", MOD(SECOND(NOW())+MINUTE(NOW()),36)+1, 1) & MID("0123456789ABCDEFGHIJKLMNOPQRSTUVWXYZ", INT(RAND()*36)+1, 1) -> FCOHKQ
A35: =Дані!A5 -> 1.2. | B35: =Дані!B5 -> - підготовка грунту в розсаднику тракторною фрезою перед висіванням насіння | G35: =IFERROR(ROUND(H35*$G$3,2), "-") -> - | H35: =Дані!C5 -> 0.098765432
A36: =Дані!A6 -> 1.3. | B36: =Дані!B6 -> - очищення площі з вибиранням коріння та деревини, що залишилася після оранки | G36: =IFERROR(ROUND(H36*$G$3,2), "-") -> - | H36: =Дані!C6 -> 1
A37: =Дані!A7 -> 1.4. | B37: =Дані!B7 -> - коткування грунту | G37: =IFERROR(ROUND(H37*$G$3,2), "-") -> - | H37: =Дані!C7 -> 0.086419753
A38: =Дані!A8 -> 2. | B38: =Дані!B8 -> Перекопування та планування обробленого ґрунту: | G38: грн/м2
A39: =Дані!A9 -> 2.1. | B39: =Дані!B9 -> - планування обробленого ґрунту граблями з розбиванням груддя, з вибиранням коріння, каміння, дернини та віднесення їх на віддаль до 40 м на середньому грунті | G39: =IFERROR(ROUND(H39*$G$4,2), "-") -> - | H39: =Дані!C9 -> 0.2893401
A40: =Дані!A10 -> 2.2. | B40: =Дані!B10 -> - перекопування лопатою на один штик обробленого грунту з розбиванням груддя та вирівнювання поверхні граблями на середньому грунті | G40: =IFERROR(ROUND(H40*$G$4,2), "-") -> - | H40: =Дані!C10 -> 1
A41: =Дані!A11 -> 3. | B41: =Дані!B11 -> Підготовка насіння до висівання: | G41: грн/кг
A42: =Дані!A12 -> 3.1. | B42: =Дані!B12 -> - засипання жолудів у ями на зимове зберігання | G42: =IFERROR(ROUND(H42*$G$5,2), "-") -> - | H42: =Дані!C12 -> 0.25
A43: =Дані!A13 -> 3.2. | B43: =Дані!B13 -> - вибирання жолудів із ями | G43: =IFERROR(ROUND(H43*$G$5,2), "-") -> - | H43: =Дані!C13 -> 0.090425532
A44: =Дані!A14 -> 3.3. | B44: =Дані!B14 -> - затарювання насіння у мішки | G44: =IFERROR(ROUND(H44*$G$5,2), "-") -> - | H44: =Дані!C14 -> 0.079787234
A45: =Дані!A15 -> 3.4. | B45: =Дані!B15 -> - вибирання насіння з під снігу | G45: =IFERROR(ROUND(H45*$G$5,2), "-") -> - | H45: =Дані!C15 -> 1
A46: =Дані!A16 -> 4. | B46: =Дані!B16 -> Стратифікація, зволоження та протруювання насіння: | G46: грн/кг
A47: =Дані!A17 -> 4.1. | B47: =Дані!B17 -> - стратифікація насіння | G47: =IFERROR(ROUND(H47*$G$6,2), "-") -> - | H47: =Дані!C17 -> 0.56575875
A48: =Дані!A18 -> 4.2. | B48: =Дані!B18 -> Перемішування та зволоження насіння у ящиках під час його зберігання та стратифікації:
A49: =Дані!A19 -> 4.2.1. | B49: =Дані!B19 -> - дрібного | G49: =IFERROR(ROUND(H49*$G$6,2), "-") -> - | H49: =Дані!C19 -> 0.37743191
A50: =Дані!A20 -> 4.2.2. | B50: =Дані!B20 -> - середнього | G50: =IFERROR(ROUND(H50*$G$6,2), "-") -> - | H50: =Дані!C20 -> 0.27003891
A51: =Дані!A21 -> 4.2.3. | B51: =Дані!B21 -> - великого | G51: =IFERROR(ROUND(H51*$G$6,2), "-") -> - | H51: =Дані!C21 -> 0.098832685
A52: =Дані!A22 -> 4.3. | B52: =Дані!B22 -> - замочування насіння у холодній воді (глід, сосна звичайна та інші) | G52: =IFERROR(ROUND(H52*$G$6,2), "-") -> - | H52: =Дані!C22 -> 0.14396887
A53: =Дані!A23 -> 4.4. | B53: =Дані!B23 -> Протруювання насіння фунгіцидами:
A54: =Дані!A24 -> 4.4.1. | B54: =Дані!B24 -> - сухим та напівсухим способом | G54: =IFERROR(ROUND(H54*$G$6,2), "-") -> - | H54: =Дані!C24 -> 0.61089494
...

Sheet Дані
A1: Коефіцієнти цін
A2: № з/п | B2: Найменування послуг | C2: Коефіцієнт ціни, од.
A3: 1. | B3: Обробіток грунту: | C3: 0
A4: 1.1. | B4: - боронування всіх різновидностей грунту в один слід бороною | C4: 0.061728395
A5: 1.2. | B5: - підготовка грунту в розсаднику тракторною фрезою перед висіванням насіння | C5: 0.098765432
A6: 1.3. | B6: - очищення площі з вибиранням коріння та деревини, що залишилася після оранки | C6: 1
A7: 1.4. | B7: - коткування грунту | C7: 0.086419753
A8: 2. | B8: Перекопування та планування обробленого ґрунту: | C8: 0
A9: 2.1. | B9: - планування обробленого ґрунту граблями з розбиванням груддя, з вибиранням коріння, каміння, дернини та віднесення їх на віддаль до 40 м на середньому грунті | C9: 0.2893401
A10: 2.2. | B10: - перекопування лопатою на один штик обробленого грунту з розбиванням груддя та вирівнювання поверхні граблями на середньому грунті | C10: 1
A11: 3. | B11: Підготовка насіння до висівання: | C11: 0
A12: 3.1. | B12: - засипання жолудів у ями на зимове зберігання | C12: 0.25
A13: 3.2. | B13: - вибирання жолудів із ями | C13: 0.090425532
A14: 3.3. | B14: - затарювання насіння у мішки | C14: 0.079787234
... A176: 28.2. | B176: - 2 рік стрижки | C176: 1
A180: ОБСЯГИ НАДАННЯ ПОСЛУГ
A181: № з/п | B181: Найменування послуг | C181: Одниці виміру | D181: № лоту
D182: 1 | E182: 2 | F182: 3 | G182: 4 | H182: 5 | I182: 6 | J182: 7 | K182: 8 | L182: 9 | M182: 10
A183: 1 | B183: Обробіток грунту | C183: м2 | D183: 28400 | E183: - | F183: - | G183: - | H183: - | I183: - | J183: - | K183: - | L183: - | M183: -
A184: 2 | B184: Перекопування та планування обробленого ґрунту | C184: м2 | D184: 22500 | E184: - | F184: - | G184: - | H184: - | I184: - | J184: - | K184: - | L184: - | M184: -
A185: 3 | B185: Підготовка насіння до висівання | C185: кг | D185: 20900 | E185: - | F185: - | G185: - | H185: - | I185: - | J185: - | K185: - | L185: - | M185: -
A186: 4 | B186: Стратифікація, зволоження та протруювання насіння | C186: кг | D186: 12250 | E186: - | F186: - | G186: - | H186: - | I186: - | J186: - | K186: - | L186: - | M186: -
A187: 5 | B187: Снігування насіння | C187: кг | D187: - | E187: - | F187: - | G187: - | H187: - | I187: - | J187: - | K187: - | L187: - | M187: -
A188: 6 | B188: Заготівля снігу та льоду для снігування насіння з піднесенням до 50 м | C188: м3 | D188: - | E188: - | F188: - | G188: - | H188: - | I188: - | J188: - | K188: - | L188: - | M188: -
A189: 7 | B189: Висівання насіння | C189: тис. пог. м. | D189: 85 | E189: - | F189: - | G189: - | H189: - | I189: - | J189: - | K189: - | L189: - | M189: -
A190: 8 | B190: Висівання насіння в короби та теплиці | C190: м2 | D190: 2000 | E190: - | F190: - | G190: - | H190: - | I190: - | J190: - | K190: - | L190: - | M190: -
A191: 9 | B191: Висівання у касети | C191: касета | D191: - | E191: - | F191: - | G191: - | H191: - | I191: - | J191: - | K191: - | L191: - | M191: -
A192: 10 | B192: Догляд за сіянцями та саджанцями | C192: м2 | D192: 220000 | E192: - | F192: - | G192: - | H192: - | I192: - | J192: - | K192: - | L192: - | M192: -
A193: 11 | B193: Покривання сіянців та саджанців затіняючою сіткою, плівкою, агроволокном | C193: м2 | D193: 17250 | E193: - | F193: - | G193: - | H193: - | I193: - | J193: - | K193: - | L193: - | M193: -
A194: 12 | B194: Обприскування та підживлення рослин | C194: м2 | D194: 10000 | E194: - | F194: - | G194: - | H194: - | I194: - | J194: - | K194: - | L194: - | M194: -
A195: 13 | B195: Прополювання посівів у теплицях або коробах | C195: м2 | D195: 22000 | E195: - | F195: - | G195: - | H195: - | I195: - | J195: - | K195: - | L195: - | M195: -
A196: 14 | B196: Розпушування грунту та прополювання посівів | C196: м2 | D196: 645000 | E196: - | F196: - | G196: - | H196: - | I196: - | J196: - | K196: - | L196: - | M196: -
A197: 15 | B197: Затінення посівів щитами | C197: щит | D197: - | E197: - | F197: - | G197: - | H197: - | I197: - | J197: - | K197: - | L197: - | M197: -
A198: 16 | B198: Послуги в теплицях та шкільних відділеннях лісових розсадників (низької вартості) | C198: тис. шт. | D198: 440 | E198: - | F198: - | G198: - | H198: - | I198: - | J198: - | K198: - | L198: - | M198: -
A199: 17 | B199: Послуги в теплицях та шкільних відділеннях лісових розсадників (середньої вартості) | C199: тис. шт. | D199: 270 | E199: - | F199: - | G199: - | H199: - | I199: - | J199: - | K199: - | L199: - | M199: -
A200: 18 | B200: Послуги в теплицях та шкільних відділеннях лісових розсадників (високої вартості) | C200: тис. шт. | D200: - | E200: - | F200: - | G200: - | H200: - | I200: - | J200: - | K200: - | L200: - | M200: -
A201: 19 | B201: Викопування декоративних саджанців без грудки землі | C201: тис. шт. | D201: 15.5 | E201: - | F201: - | G201: - | H201: - | I201: - | J201: - | K201: - | L201: - | M201: -
A202: 20 | B202: Викопування декоративних саджанців з грудою землі | C202: тис. шт. | D202: 14 | E202: - | F202: - | G202: - | H202: - | I202: - | J202: - | K202: - | L202: - | M202: -
A203: 21 | B203: Топіарна стрижка | C203: шт. | D203: 22000 | E203: - | F203: - | G203: - | H203: - | I203: - | J203: - | K203: - | L203: - | M203: -
A204: 22 | B204: Приготування земляної (торфяної) суміші для коробів та теплиць | C204: м3 | D204: 142 | E204: - | F204: - | G204: - | H204: - | I204: - | J204: - | K204: - | L204: - | M204: -
...
